Workbook

Sheet overview
A1: Job Search Overview
A2: Last exported | B2: 46202.707
A4: Use Status to track each role. Set Status to applied when you apply, then add the date and details in Notes.
A6: Status | B6: Count
A7: new | B7: =COUNTIF(jobs!$B:$B,A7)
A8: applied | B8: =COUNTIF(jobs!$B:$B,A8)
A9: interview | B9: =COUNTIF(jobs!$B:$B,A9)
A10: offer | B10: =COUNTIF(jobs!$B:$B,A10)
A11: rejected | B11: =COUNTIF(jobs!$B:$B,A11)
A12: ignore | B12: =COUNTIF(jobs!$B:$B,A12)
A13: archive | B13: =COUNTIF(jobs!$B:$B,A13)
A14: closed | B14: =COUNTIF(jobs!$B:$B,A14)
A17: Priority | B17: Count
A18: P1 Apply | B18: =COUNTIF(jobs!$C:$C,A18)
A19: P2 Strong | B19: =COUNTIF(jobs!$C:$C,A19)
A20: P3 Maybe | B20: =COUNTIF(jobs!$C:$C,A20)
A21: P4 Low | B21: =COUNTIF(jobs!$C:$C,A21)
A22: Applied | B22: =COUNTIF(jobs!$C:$C,A22)
A23: Interview | B23: =COUNTIF(jobs!$C:$C,A23)
A24: Offer | B24: =COUNTIF(jobs!$C:$C,A24)
A27: Top Jobs to Apply For
A28: Priority | B28: Score | C28: Experience | D28: Status | E28: Title | F28: Company | G28: Location | H28: Closes | I28: Apply | J28: Why Claude likes it
A29: P1 Apply | B29: 8.5 | C29: Junior | D29: new | E29: Junior Python Developer | F29: Station | G29: London Area, United Kingdom | I29: Open posting | J29: Junior Python Developer title, Python, REST APIs, SQL/PostgreSQL, Django/Flask/FastAPI all match core and adjacent skills; London hybrid is within remote-ok policy.
A30: P1 Apply | B30: 8.5 | C30: Graduate/Entry | D30: new | E30: Graduate Digital Design Engineer | F30: Renesas Electronics | G30: Edinburgh, Scotland, UK | I30: Open posting | J30: FPGA/Verilog dissertation and digital design skills match RTL/HDL requirements; SystemVerilog vs Verilog minor gap.
A31: P1 Apply | B31: 8.2 | C31: Graduate/Entry | D31: new | E31: Graduate Digital Design Engineer | F31: targetjobs UK | G31: Edinburgh, Scotland, UK | I31: Open posting | J31: Graduate Digital Design Engineer matches core target role; Verilog, FPGA, Python, Git all evidenced; SystemVerilog is a minor gap.
A32: P1 Apply | B32: 8 | C32: Junior | D32: new | E32: Full Stack Engineer | F32: Fortray Global Service Limited | G32: England, United Kingdom | I32: Open posting | J32: Strong match for early-career full-stack role; Python, JS, REST APIs, Git, React, MongoDB, and Agile all present in profile.
A33: P2 Strong | B33: 7.8 | C33: Graduate/Entry | D33: new | E33: Junior Software Engineer / Computer Science Graduate (Remote) | F33: CTW Content Protection | G33: GB | I33: Open posting | J33: Python, SQL/MySQL, APIs, Docker, backend dev all directly match core skills; fully remote, salary £30-35k above floor, graduate-level role.
A34: P2 Strong | B34: 7.5 | C34: Junior | D34: new | E34: Junior Data Engineer - Integration | F34: Ocean Infinity | G34: London, England, UK | I34: Open posting | J34: Python, SQL, API integration, and backend data pipeline experience closely match this junior 0-2 year data engineering role.
A35: P2 Strong | B35: 7.5 | C35: Junior | D35: new | E35: Junior Data Engineer - Integration | F35: Ocean Infinity | G35: Southampton, England, UK | I35: Open posting | J35: Python, SQL, API integration, and backend data pipeline experience closely match this junior 0-2 year data engineering role.
A36: P2 Strong | B36: 7.5 | C36: Unspecified | D36: new | E36: GPU Datapath Design Engineer | F36: Imagination Technologies | G36: Kings Langley, England, UK | I36: Open posting | J36: FPGA/Verilog dissertation and digital design skills align well; no GPU-specific or ASIC experience, but training offered.
A37: P2 Strong | B37: 7.5 | C37: Graduate/Entry | D37: new | E37: Graduate R&D Engineer – System & Architecture | F37: Microchip Technology | G37: Whiteley, ENG, GB | I37: Open posting | J37: Graduate/early-career role matching embedded firmware, signal processing, and hardware-software interface skills from candidate's profile.
A38: P2 Strong | B38: 7.5 | C38: Unspecified | D38: new | E38: Embedded Engineer - IoT Sensors & Gateways / Smart Buildings | F38: Pressac Communications | G38: Nottingham, England, UK | I38: Open posting | J38: Strong IoT/LoRaWAN, STM32, Raspberry Pi, and embedded C/Python match; missing commercial firmware experience and specific IDE tools (STM32 IDE, Keil).
A39: P2 Strong | B39: 7.3 | C39: Unspecified | D39: new | E39: Computer Engineering | F39: Alignerr | G39: Manchester, England, UK | I39: Open posting | J39: Strong FPGA, Verilog, embedded systems, and IoT skills align; pursuing MEng meets 'Masters pursuing' requirement; freelance contract only.
A40: P2 Strong | B40: 7.2 | C40: Graduate/Entry | D40: new | E40: Graduate Engineer | F40: Spectrum IT Recruitment | G40: Fareham, England, UK | I40: Open posting | J40: Graduate Electronic Engineering role matching FPGA, Verilog, Python, DSP, and Linux skills; Fareham location is outside 60-mile radius but role suits profile well.
... A43: P2 Strong | B43: 7.2 | C43: Unspecified | D43: new | E43: Computer Engineering | F43: Alignerr | G43: Birmingham, England, UK | I43: Open posting | J43: FPGA, Verilog, embedded systems, and IoT match core JD domains; MEng satisfies degree requirement; hourly contract not a graduate role.

Sheet jobs
A1: Action | B1: Score | C1: Experience | D1: Title | E1: Company | F1: Location | G1: Salary | H1: Closes | I1: Days Left | J1: Apply | K1: Why Claude likes it | L1: Status | M1: Notes | N1: Job ID | O1: Posted | P1: Source | Q1: Matched Keywords | R1: Query | S1: Salary Min | T1: Salary Max | U1: First Seen | V1: Ranker Ver.
A2: =IF($L2="applied","Applied",IF($L2="interview","Interview",IF($L2="offer","Offer",IF($L2="rejected","Rejected",IF($L2="ignore","Ignore",IF($L2="archive","Archive",IF($L2="closed","Closed",IF($B2="","Unscored",IF(AND($B2>=8,OR($H2="",$H2-TODAY()<=14)),"P1 Apply",IF($B2>=7,"P2 Strong",IF($B2>=5,"P3 Maybe","P4 Low"))))))))))) | B2: 8.5 | C2: Junior | D2: Junior Python Developer | E2: Station | F2: London Area, United Kingdom | I2: =IF($H2="","",$H2-TODAY()) | J2: Open posting | K2: Junior Python Developer title, Python, REST APIs, SQL/PostgreSQL, Django/Flask/FastAPI all match core and adjacent skills; London hybrid is within remote-ok policy. | L2: new | N2: 46f1d6296a3c9d0be7206d78909b5b20ff30a25d | P2: jobspy | Q2: Python, REST APIs, SQL, FastAPI, Flask | R2: Junior Python Developer | U2: 46192 | V2: v2-cv-accuracy-13b988b18da8ea7d
A3: =IF($L3="applied","Applied",IF($L3="interview","Interview",IF($L3="offer","Offer",IF($L3="rejected","Rejected",IF($L3="ignore","Ignore",IF($L3="archive","Archive",IF($L3="closed","Closed",IF($B3="","Unscored",IF(AND($B3>=8,OR($H3="",$H3-TODAY()<=14)),"P1 Apply",IF($B3>=7,"P2 Strong",IF($B3>=5,"P3 Maybe","P4 Low"))))))))))) | B3: 8.5 | C3: Graduate/Entry | D3: Graduate Digital Design Engineer | E3: Renesas Electronics | F3: Edinburgh, Scotland, UK | I3: =IF($H3="","",$H3-TODAY()) | J3: Open posting | K3: FPGA/Verilog dissertation and digital design skills match RTL/HDL requirements; SystemVerilog vs Verilog minor gap. | L3: new | N3: 9384b9741d9c0cb3b1a7ef6886b9de5772942944 | O3: 46176 | P3: jobspy | Q3: Verilog, FPGA, Python, Git, digital design | R3: Graduate FPGA Engineer Verilog Vivado | U3: 46192 | V3: v2-cv-accuracy-13b988b18da8ea7d
A4: =IF($L4="applied","Applied",IF($L4="interview","Interview",IF($L4="offer","Offer",IF($L4="rejected","Rejected",IF($L4="ignore","Ignore",IF($L4="archive","Archive",IF($L4="closed","Closed",IF($B4="","Unscored",IF(AND($B4>=8,OR($H4="",$H4-TODAY()<=14)),"P1 Apply",IF($B4>=7,"P2 Strong",IF($B4>=5,"P3 Maybe","P4 Low"))))))))))) | B4: 8.2 | C4: Graduate/Entry | D4: Graduate Digital Design Engineer | E4: targetjobs UK | F4: Edinburgh, Scotland, UK | I4: =IF($H4="","",$H4-TODAY()) | J4: Open posting | K4: Graduate Digital Design Engineer matches core target role; Verilog, FPGA, Python, Git all evidenced; SystemVerilog is a minor gap. | L4: new | N4: e0f837217efc0250adb5a458ad8ad16bf518ff2a | O4: 46191 | P4: jobspy | Q4: Verilog, FPGA, Python, Git, digital design | R4: Graduate FPGA Engineer UK remote | U4: 46192 | V4: v2-cv-accuracy-13b988b18da8ea7d
A5: =IF($L5="applied","Applied",IF($L5="interview","Interview",IF($L5="offer","Offer",IF($L5="rejected","Rejected",IF($L5="ignore","Ignore",IF($L5="archive","Archive",IF($L5="closed","Closed",IF($B5="","Unscored",IF(AND($B5>=8,OR($H5="",$H5-TODAY()<=14)),"P1 Apply",IF($B5>=7,"P2 Strong",IF($B5>=5,"P3 Maybe","P4 Low"))))))))))) | B5: 8 | C5: Junior | D5: Full Stack Engineer | E5: Fortray Global Service Limited | F5: England, United Kingdom | I5: =IF($H5="","",$H5-TODAY()) | J5: Open posting | K5: Strong match for early-career full-stack role; Python, JS, REST APIs, Git, React, MongoDB, and Agile all present in profile. | L5: new | N5: 6923b68fabb4fd9d9bc9051a629b6694c6be29e7 | O5: 46188 | P5: jobspy | Q5: Python, JavaScript, REST APIs, Git, React | R5: entry level Full Stack Developer | U5: 46192 | V5: v2-cv-accuracy-13b988b18da8ea7d
A6: =IF($L6="applied","Applied",IF($L6="interview","Interview",IF($L6="offer","Offer",IF($L6="rejected","Rejected",IF($L6="ignore","Ignore",IF($L6="archive","Archive",IF($L6="closed","Closed",IF($B6="","Unscored",IF(AND($B6>=8,OR($H6="",$H6-TODAY()<=14)),"P1 Apply",IF($B6>=7,"P2 Strong",IF($B6>=5,"P3 Maybe","P4 Low"))))))))))) | B6: 7.8 | C6: Graduate/Entry | D6: Junior Software Engineer / Computer Science Graduate (Remote) | E6: CTW Content Protection | F6: GB | I6: =IF($H6="","",$H6-TODAY()) | J6: Open posting | K6: Python, SQL/MySQL, APIs, Docker, backend dev all directly match core skills; fully remote, salary £30-35k above floor, graduate-level role. | L6: new | N6: d0d916f9adcdabb6ccab921b95bc4589da3e3c50 | O6: 46188 | P6: jobspy | Q6: Python, MySQL, Docker, API integration, SQL | R6: Platform Engineer backend Python SQL graduate | U6: 46192 | V6: v2-cv-accuracy-13b988b18da8ea7d
A7: =IF($L7="applied","Applied",IF($L7="interview","Interview",IF($L7="offer","Offer",IF($L7="rejected","Rejected",IF($L7="ignore","Ignore",IF($L7="archive","Archive",IF($L7="closed","Closed",IF($B7="","Unscored",IF(AND($B7>=8,OR($H7="",$H7-TODAY()<=14)),"P1 Apply",IF($B7>=7,"P2 Strong",IF($B7>=5,"P3 Maybe","P4 Low"))))))))))) | B7: 7.5 | C7: Junior | D7: Junior Data Engineer - Integration | E7: Ocean Infinity | F7: London, England, UK | I7: =IF($H7="","",$H7-TODAY()) | J7: Open posting | K7: Python, SQL, API integration, and backend data pipeline experience closely match this junior 0-2 year data engineering role. | L7: new | N7: 1fe209d1974bbaeb8dc5366467e400e6e0ef17db | P7: jobspy | Q7: Python, SQL, API integration, MySQL, backend development | R7: Junior Data Engineer Python SQL MySQL | U7: 46195 | V7: v2-cv-accuracy-13b988b18da8ea7d
A8: =IF($L8="applied","Applied",IF($L8="interview","Interview",IF($L8="offer","Offer",IF($L8="rejected","Rejected",IF($L8="ignore","Ignore",IF($L8="archive","Archive",IF($L8="closed","Closed",IF($B8="","Unscored",IF(AND($B8>=8,OR($H8="",$H8-TODAY()<=14)),"P1 Apply",IF($B8>=7,"P2 Strong",IF($B8>=5,"P3 Maybe","P4 Low"))))))))))) | B8: 7.5 | C8: Junior | D8: Junior Data Engineer - Integration | E8: Ocean Infinity | F8: Southampton, England, UK | I8: =IF($H8="","",$H8-TODAY()) | J8: Open posting | K8: Python, SQL, API integration, and backend data pipeline experience closely match this junior 0-2 year data engineering role. | L8: new | N8: 06819d866830536a2f612df53be3d32627089eb3 | P8: jobspy | Q8: Python, SQL, API integration, MySQL, backend development | R8: Junior Data Engineer Python SQL MySQL | U8: 46195 | V8: v2-cv-accuracy-13b988b18da8ea7d
A9: =IF($L9="applied","Applied",IF($L9="interview","Interview",IF($L9="offer","Offer",IF($L9="rejected","Rejected",IF($L9="ignore","Ignore",IF($L9="archive","Archive",IF($L9="closed","Closed",IF($B9="","Unscored",IF(AND($B9>=8,OR($H9="",$H9-TODAY()<=14)),"P1 Apply",IF($B9>=7,"P2 Strong",IF($B9>=5,"P3 Maybe","P4 Low"))))))))))) | B9: 7.5 | C9: Unspecified | D9: GPU Datapath Design Engineer | E9: Imagination Technologies | F9: Kings Langley, England, UK | I9: =IF($H9="","",$H9-TODAY()) | J9: Open posting | K9: FPGA/Verilog dissertation and digital design skills align well; no GPU-specific or ASIC experience, but training offered. | L9: new | N9: d00bbbc4ca69b9bb8923cb0f10a4b434ea348ef2 | O9: 46178 | P9: jobspy | Q9: Verilog, FPGA, Python, digital design, DSP | R9: Graduate FPGA Engineer Verilog Vivado | U9: 46194 | V9: v2-cv-accuracy-13b988b18da8ea7d
A10: =IF($L10="applied","Applied",IF($L10="interview","Interview",IF($L10="offer","Offer",IF($L10="rejected","Rejected",IF($L10="ignore","Ignore",IF($L10="archive","Archive",IF($L10="closed","Closed",IF($B10="","Unscored",IF(AND($B10>=8,OR($H10="",$H10-TODAY()<=14)),"P1 Apply",IF($B10>=7,"P2 Strong",IF($B10>=5,"P3 Maybe","P4 Low"))))))))))) | B10: 7.5 | C10: Graduate/Entry | D10: Graduate R&D Engineer – System & Architecture | E10: Microchip Technology | F10: Whiteley, ENG, GB | I10: =IF($H10="","",$H10-TODAY()) | J10: Open posting | K10: Graduate/early-career role matching embedded firmware, signal processing, and hardware-software interface skills from candidate's profile. | L10: new | N10: 739a7a4fbff2e88cb93edf982e7e4550aea7d26c | O10: 46190 | P10: jobspy | Q10: embedded systems, C, STM32, signal processing, Python | R10: Graduate Systems Engineer embedded hardware software | U10: 46192 | V10: v2-cv-accuracy-13b988b18da8ea7d
A11: =IF($L11="applied","Applied",IF($L11="interview","Interview",IF($L11="offer","Offer",IF($L11="rejected","Rejected",IF($L11="ignore","Ignore",IF($L11="archive","Archive",IF($L11="closed","Closed",IF($B11="","Unscored",IF(AND($B11>=8,OR($H11="",$H11-TODAY()<=14)),"P1 Apply",IF($B11>=7,"P2 Strong",IF($B11>=5,"P3 Maybe","P4 Low"))))))))))) | B11: 7.5 | C11: Unspecified | D11: Embedded Engineer - IoT Sensors & Gateways / Smart Buildings | E11: Pressac Communications | F11: Nottingham, England, UK | I11: =IF($H11="","",$H11-TODAY()) | J11: Open posting | K11: Strong IoT/LoRaWAN, STM32, Raspberry Pi, and embedded C/Python match; missing commercial firmware experience and specific IDE tools (STM32 IDE, Keil). | L11: new | N11: aae6ade6b34a2ad208b86b4d2dad8ba09445fbbe | O11: 46189 | P11: jobspy | Q11: LoRaWAN, STM32, Raspberry Pi, Python, embedded systems | R11: Junior Embedded Software Engineer STM32 | U11: 46192 | V11: v2-cv-accuracy-13b988b18da8ea7d
A12: =IF($L12="applied","Applied",IF($L12="interview","Interview",IF($L12="offer","Offer",IF($L12="rejected","Rejected",IF($L12="ignore","Ignore",IF($L12="archive","Archive",IF($L12="closed","Closed",IF($B12="","Unscored",IF(AND($B12>=8,OR($H12="",$H12-TODAY()<=14)),"P1 Apply",IF($B12>=7,"P2 Strong",IF($B12>=5,"P3 Maybe","P4 Low"))))))))))) | B12: 7.3 | C12: Unspecified | D12: Computer Engineering | E12: Alignerr | F12: Manchester, England, UK | I12: =IF($H12="","",$H12-TODAY()) | J12: Open posting | K12: Strong FPGA, Verilog, embedded systems, and IoT skills align; pursuing MEng meets 'Masters pursuing' requirement; freelance contract only. | L12: new | N12: 925fcb619fc33cf24860169a4c291257d865a046 | O12: 46189 | P12: jobspy | Q12: FPGA, Verilog, embedded systems, IoT, digital design | R12: Graduate Computer Engineer digital design | U12: 46194 | V12: v2-cv-accuracy-13b988b18da8ea7d
A13: =IF($L13="applied","Applied",IF($L13="interview","Interview",IF($L13="offer","Offer",IF($L13="rejected","Rejected",IF($L13="ignore","Ignore",IF($L13="archive","Archive",IF($L13="closed","Closed",IF($B13="","Unscored",IF(AND($B13>=8,OR($H13="",$H13-TODAY()<=14)),"P1 Apply",IF($B13>=7,"P2 Strong",IF($B13>=5,"P3 Maybe","P4 Low"))))))))))) | B13: 7.2 | C13: Graduate/Entry | D13: Graduate Engineer | E13: Spectrum IT Recruitment | F13: Fareham, England, UK | I13: =IF($H13="","",$H13-TODAY()) | J13: Open posting | K13: Graduate Electronic Engineering role matching FPGA, Verilog, Python, DSP, and Linux skills; Fareham location is outside 60-mile radius but role suits profile well. | L13: new | N13: 743e2618064c9780f0dbf2e7134ea6741dfe6ce1 | O13: 46197 | P13: jobspy | Q13: FPGA, Verilog, Python, digital design, signal processing | R13: Graduate Signal Processing Engineer DSP FPGA | U13: 46199 | V13: v2-cv-accuracy-13b988b18da8ea7d
A14: =IF($L14="applied","Applied",IF($L14="interview","Interview",IF($L14="offer","Offer",IF($L14="rejected","Rejected",IF($L14="ignore","Ignore",IF($L14="archive","Archive",IF($L14="closed","Closed",IF($B14="","Unscored",IF(AND($B14>=8,OR($H14="",$H14-TODAY()<=14)),"P1 Apply",IF($B14>=7,"P2 Strong",IF($B14>=5,"P3 Maybe","P4 Low"))))))))))) | B14: 7.2 | C14: Unspecified | D14: Computer Engineering Expert - AI Content Specialist | E14: Alignerr | F14: Oxford, England, UK | I14: =IF($H14="","",$H14-TODAY()) | J14: Open posting | K14: MEng in ECE (pursuing Masters-level), FPGA/Verilog/embedded systems match well; contract/hourly role not a graduate permanent position. | L14: new | N14: 5b302bdc4392578b1e67cf6b53ca56f4c547210d | O14: 46191 | P14: jobspy | Q14: FPGA, Verilog, embedded systems, digital design, SolidWorks | R14: Graduate Computer Engineer digital design | U14: 46194 | V14: v2-cv-accuracy-13b988b18da8ea7d
A15: =IF($L15="applied","Applied",IF($L15="interview","Interview",IF($L15="offer","Offer",IF($L15="rejected","Rejected",IF($L15="ignore","Ignore",IF($L15="archive","Archive",IF($L15="closed","Closed",IF($B15="","Unscored",IF(AND($B15>=8,OR($H15="",$H15-TODAY()<=14)),"P1 Apply",IF($B15>=7,"P2 Strong",IF($B15>=5,"P3 Maybe","P4 Low"))))))))))) | B15: 7.2 | C15: Unspecified | D15: Computer Engineering Expert - AI Content Specialist | E15: Alignerr | F15: Birmingham, England, UK | I15: =IF($H15="","",$H15-TODAY()) | J15: Open posting | K15: MEng in ECE (pursuing Masters-level), FPGA/Verilog/embedded systems match well; contract/hourly role not a graduate permanent position. | L15: new | N15: 4ada3c9d583603a2f905958297b3e23d04acb4bf | O15: 46191 | P15: jobspy | Q15: FPGA, Verilog, embedded systems, digital design, SolidWorks | R15: Graduate Computer Engineer digital design | U15: 46194 | V15: v2-cv-accuracy-13b988b18da8ea7d
A16: =IF($L16="applied","Applied",IF($L16="interview","Interview",IF($L16="offer","Offer",IF($L16="rejected","Rejected",IF($L16="ignore","Ignore",IF($L16="archive","Archive",IF($L16="closed","Closed",IF($B16="","Unscored",IF(AND($B16>=8,OR($H16="",$H16-TODAY()<=14)),"P1 Apply",IF($B16>=7,"P2 Strong",IF($B16>=5,"P3 Maybe","P4 Low"))))))))))) | B16: 7.2 | C16: Unspecified | D16: Computer Engineering | E16: Alignerr | F16: Birmingham, England, UK | I16: =IF($H16="","",$H16-TODAY()) | J16: Open posting | K16: FPGA, Verilog, embedded systems, and IoT match core JD domains; MEng satisfies degree requirement; hourly contract not a graduate role. | L16: new | N16: 293e437b19ac5c627215558adf56744130a51fb4 | O16: 46188 | P16: jobspy | Q16: FPGA, Verilog, embedded systems, IoT, SolidWorks | R16: Graduate Computer Engineer digital design | U16: 46194 | V16: v2-cv-accuracy-13b988b18da8ea7d
A17: =IF($L17="applied","Applied",IF($L17="interview","Interview",IF($L17="offer","Offer",IF($L17="rejected","Rejected",IF($L17="ignore","Ignore",IF($L17="archive","Archive",IF($L17="closed","Closed",IF($B17="","Unscored",IF(AND($B17>=8,OR($H17="",$H17-TODAY()<=14)),"P1 Apply",IF($B17>=7,"P2 Strong",IF($B17>=5,"P3 Maybe","P4 Low"))))))))))) | B17: 7.2 | C17: Unspecified | D17: Computer Engineering | E17: Alignerr | F17: Edinburgh, Scotland, UK | I17: =IF($H17="","",$H17-TODAY()) | J17: Open posting | K17: FPGA, Verilog, embedded systems, and IoT match core JD domains; MEng satisfies degree requirement; hourly contract not a graduate role. | L17: new | N17: 6b8e2c2d38d8288a7329fdc7855bae1467ecb3a1 | O17: 46188 | P17: jobspy | Q17: FPGA, Verilog, embedded systems, IoT, SolidWorks | R17: Graduate Computer Engineer digital design | U17: 46194 | V17: v2-cv-accuracy-13b988b18da8ea7d
A18: =IF($L18="applied","Applied",IF($L18="interview","Interview",IF($L18="offer","Offer",IF($L18="rejected","Rejected",IF($L18="ignore","Ignore",IF($L18="archive","Archive",IF($L18="closed","Closed",IF($B18="","Unscored",IF(AND($B18>=8,OR($H18="",$H18-TODAY()<=14)),"P1 Apply",IF($B18>=7,"P2 Strong",IF($B18>=5,"P3 Maybe","P4 Low"))))))))))) | B18: 7.2 | C18: Junior | D18: Digital Design Engineer (AP) | E18: Cirrus Logic | F18: Edinburgh, Scotland, UK | I18: =IF($H18="","",$H18-TODAY()) | J18: Open posting | K18: Verilog and FPGA skills match well; gaps in SystemVerilog, synthesis flows, CDC tools, and Edinburgh location adds friction. | L18: new | N18: a1cc467249a00aa9b92d12e7648d43e8f69f41e6 | O18: 46182 | P18: jobspy | Q18: Verilog, FPGA, Vivado, digital design, DSP | R18: Graduate Digital Design Engineer FPGA | U18: 46193 | V18: v2-cv-accuracy-13b988b18da8ea7d
A19: =IF($L19="applied","Applied",IF($L19="interview","Interview",IF($L19="offer","Offer",IF($L19="rejected","Rejected",IF($L19="ignore","Ignore",IF($L19="archive","Archive",IF($L19="closed","Closed",IF($B19="","Unscored",IF(AND($B19>=8,OR($H19="",$H19-TODAY()<=14)),"P1 Apply",IF($B19>=7,"P2 Strong",IF($B19>=5,"P3 Maybe","P4 Low"))))))))))) | B19: 7.2 | C19: Senior/Lead | D19: Software Engineer | E19: Crowder Consulting | F19: Birkenhead, ENG, GB | I19: =IF($H19="","",$H19-TODAY()) | J19: Open posting | K19: Python, SQL, Docker, REST APIs, and backend dev match well; no Java or cloud-platform experience evident in profile. | L19: new | N19: 8bae9f5a399a163efc3fbe14a19862a5fa85f27a | O19: 46183 | P19: jobspy | Q19: Python, SQL, Docker, MySQL, REST APIs | R19: Graduate Software Engineer Python Docker | U19: 46193 | V19: v2-cv-accuracy-13b988b18da8ea7d
A20: =IF($L20="applied","Applied",IF($L20="interview","Interview",IF($L20="offer","Offer",IF($L20="rejected","Rejected",IF($L20="ignore","Ignore",IF($L20="archive","Archive",IF($L20="closed","Closed",IF($B20="","Unscored",IF(AND($B20>=8,OR($H20="",$H20-TODAY()<=14)),"P1 Apply",IF($B20>=7,"P2 Strong",IF($B20>=5,"P3 Maybe","P4 Low"))))))))))) | B20: 7.2 | C20: Mid-level | D20: Verification Engineer (f/m/d) | E20: Renesas | F20: Edinburgh, SCT, GB | I20: =IF($H20="","",$H20-TODAY()) | J20: Open posting | K20: FPGA dissertation, Verilog, digital design, and Git strongly match; SystemVerilog/UVM not explicitly evidenced but role accepts academic FPGA experience. | L20: new | N20: 656ebc383881b04d4b39edc8c7c8498c5a04a43f | O20: 46185 | P20: jobspy | Q20: Verilog, FPGA, digital design, Python, Git | R20: Digital Design Engineer FPGA Verilog | U20: 46193 | V20: v2-cv-accuracy-13b988b18da8ea7d
A21: =IF($L21="applied","Applied",IF($L21="interview","Interview",IF($L21="offer","Offer",IF($L21="rejected","Rejected",IF($L21="ignore","Ignore",IF($L21="archive","Archive",IF($L21="closed","Closed",IF($B21="","Unscored",IF(AND($B21>=8,OR($H21="",$H21-TODAY()<=14)),"P1 Apply",IF($B21>=7,"P2 Strong",IF($B21>=5,"P3 Maybe","P4 Low"))))))))))) | B21: 7 | C21: Mid-level | D21: Embedded Software Engineer | E21: Archangel Autonomy | F21: Oxford, England, UK | I21: =IF($H21="","",$H21-TODAY()) | J21: Open posting | K21: LoRaWAN IoT and embedded systems match well; role requires commercial C/C++ firmware delivery experience which exceeds the candidate's internship-level evidence. | L21: new | N21: a975ebe001a211a85c04582006e39137d419e9a4 | P21: jobspy | Q21: LoRaWAN, IoT, embedded systems, Raspberry Pi, Python | R21: Junior Firmware Engineer STM32 C Python | U21: 46199 | V21: v2-cv-accuracy-13b988b18da8ea7d
A22: =IF($L22="applied","Applied",IF($L22="interview","Interview",IF($L22="offer","Offer",IF($L22="rejected","Rejected",IF($L22="ignore","Ignore",IF($L22="archive","Archive",IF($L22="closed","Closed",IF($B22="","Unscored",IF(AND($B22>=8,OR($H22="",$H22-TODAY()<=14)),"P1 Apply",IF($B22>=7,"P2 Strong",IF($B22>=5,"P3 Maybe","P4 Low"))))))))))) | B22: 7 | C22: Junior | D22: Manchester - Junior Developer - Elevate Programme | E22: Vantage Point Global | F22: Manchester, England, UK | I22: =IF($H22="","",$H22-TODAY()) | J22: Open posting | K22: Junior developer role matching experience level; JavaScript, APIs, SQL, and databases align well, though enterprise/consultancy platform focus is a gap. | L22: new | N22: 49d744a689360e4fd2e2433a67a0579f5163bc2a | O22: 46190 | P22: jobspy | Q22: JavaScript, SQL, API integration, Git, backend development | R22: Graduate Verification Engineer digital design | U22: 46194 | V22: v2-cv-accuracy-13b988b18da8ea7d
A23: =IF($L23="applied","Applied",IF($L23="interview","Interview",IF($L23="offer","Offer",IF($L23="rejected","Rejected",IF($L23="ignore","Ignore",IF($L23="archive","Archive",IF($L23="closed","Closed",IF($B23="","Unscored",IF(AND($B23>=8,OR($H23="",$H23-TODAY()<=14)),"P1 Apply",IF($B23>=7,"P2 Strong",IF($B23>=5,"P3 Maybe","P4 Low"))))))))))) | B23: 7 | C23: Junior | D23: Junior Full Stack Developer | E23: Haystack | F23: London, England, UK | I23: =IF($H23="","",$H23-TODAY()) | J23: Open posting | K23: JavaScript, React, Node.js, APIs and AWS match adjacent skills; fully remote suits profile; limited JD detail on seniority requirements. | L23: new | N23: eacb8ba7c567f6e07699dc4724081786e55aecf1 | P23: jobspy | Q23: JavaScript, React, Node.js, REST APIs, AWS | R23: junior Graduate Software Developer | U23: 46192 | V23: v2-cv-accuracy-13b988b18da8ea7d
A24: =IF($L24="applied","Applied",IF($L24="interview","Interview",IF($L24="offer","Offer",IF($L24="rejected","Rejected",IF($L24="ignore","Ignore",IF($L24="archive","Archive",IF($L24="closed","Closed",IF($B24="","Unscored",IF(AND($B24>=8,OR($H24="",$H24-TODAY()<=14)),"P1 Apply",IF($B24>=7,"P2 Strong",IF($B24>=5,"P3 Maybe","P4 Low"))))))))))) | B24: 7 | C24: Mid-level | D24: Software Engineer - Graduates Considered | E24: RedTech Recruitment | F24: London Area, United Kingdom | I24: =IF($H24="","",$H24-TODAY()) | J24: Open posting | K24: Graduate-level Python role matching core skills; Cambridge/London location is outside 60-mile radius but hybrid is partial mitigation. | L24: new | N24: 845cfaa77fa2493790127833cc58821b2ef358c5 | P24: jobspy | Q24: Python, Docker, JavaScript, Git | R24: Junior Python Developer Docker Kubernetes Sheffield | U24: 46192 | V24: v2-cv-accuracy-13b988b18da8ea7d
A25: =IF($L25="applied","Applied",IF($L25="interview","Interview",IF($L25="offer","Offer",IF($L25="rejected","Rejected",IF($L25="ignore","Ignore",IF($L25="archive","Archive",IF($L25="closed","Closed",IF($B25="","Unscored",IF(AND($B25>=8,OR($H25="",$H25-TODAY()<=14)),"P1 Apply",IF($B25>=7,"P2 Strong",IF($B25>=5,"P3 Maybe","P4 Low"))))))))))) | B25: 7 | C25: Graduate/Entry | D25: Graduate Validation Engineer | E25: Cirrus Logic | F25: Edinburgh, Scotland, UK | I25: =IF($H25="","",$H25-TODAY()) | J25: Open posting | K25: Graduate validation role suits experience level; Python, FPGA, digital/mixed-signal debugging align, though PCB design and LabVIEW are minor gaps. | L25: new | N25: 3cd185f1454f7f595f7f6679e2076489236211aa | O25: 46170 | P25: jobspy | Q25: Python, FPGA, digital design, embedded systems, signal processing | R25: Graduate Verification Engineer Verilog digital | U25: 46192 | V25: v2-cv-accuracy-13b988b18da8ea7d
A26: =IF($L26="applied","Applied",IF($L26="interview","Interview",IF($L26="offer","Offer",IF($L26="rejected","Rejected",IF($L26="ignore","Ignore",IF($L26="archive","Archive",IF($L26="closed","Closed",IF($B26="","Unscored",IF(AND($B26>=8,OR($H26="",$H26-TODAY()<=14)),"P1 Apply",IF($B26>=7,"P2 Strong",IF($B26>=5,"P3 Maybe","P4 Low"))))))))))) | B26: 6.5 | C26: Graduate/Entry | D26: Graduate R&D Engineer – System & Architecture | E26: Microchip Technology Inc. | F26: Whiteley, England, UK | I26: =IF($H26="","",$H26-TODAY()) | J26: Open posting | K26: Embedded firmware and signal processing align well; analogue/capacitive sensing expertise is a gap not evidenced in profile. | L26: new | N26: 1bba1621a27c81939832e15f49a5a0f64e74cb5e | P26: jobspy | Q26: embedded systems, digital design, signal processing, C, DSP | R26: Graduate Systems Engineer hardware software Sheffield | U26: 46196 | V26: v2-cv-accuracy-13b988b18da8ea7d
A27: =IF($L27="applied","Applied",IF($L27="interview","Interview",IF($L27="offer","Offer",IF($L27="rejected","Rejected",IF($L27="ignore","Ignore",IF($L27="archive","Archive",IF($L27="closed","Closed",IF($B27="","Unscored",IF(AND($B27>=8,OR($H27="",$H27-TODAY()<=14)),"P1 Apply",IF($B27>=7,"P2 Strong",IF($B27>=5,"P3 Maybe","P4 Low"))))))))))) | B27: 6.5 | C27: Senior/Lead | D27: Software Engineer | E27: Venn Telecom | F27: Exeter, England, UK | I27: =IF($H27="","",$H27-TODAY()) | J27: Open posting | K27: Python, SQL, Docker, Node.js, and backend dev match well, but Exeter location is outside 60-mile radius and no cloud platform experience evidenced. | L27: new | N27: ecebc3e7669434abafc4e4ebf5461fd3200ec838 | O27: 46183 | P27: jobspy | Q27: Python, SQL, Docker, MySQL, Node.js | R27: Graduate Software Engineer Python backend | U27: 46195 | V27: v2-cv-accuracy-13b988b18da8ea7d
A28: =IF($L28="applied","Applied",IF($L28="interview","Interview",IF($L28="offer","Offer",IF($L28="rejected","Rejected",IF($L28="ignore","Ignore",IF($L28="archive","Archive",IF($L28="closed","Closed",IF($B28="","Unscored",IF(AND($B28>=8,OR($H28="",$H28-TODAY()<=14)),"P1 Apply",IF($B28>=7,"P2 Strong",IF($B28>=5,"P3 Maybe","P4 Low"))))))))))) | B28: 6.5 | C28: Unspecified | D28: Computer Engineering | E28: Alignerr | F28: Cambridge, England, UK | I28: =IF($H28="","",$H28-TODAY()) | J28: Open posting | K28: FPGA/Verilog dissertation, embedded systems, and digital design directly match core duties; MEng pursuing satisfies advanced degree requirement. | L28: new | N28: c3110f690efa5200346d49a4b255139a6e4b9afb | O28: 46192 | P28: jobspy | Q28: FPGA, Verilog, embedded systems, digital design, SolidWorks | R28: Graduate Computer Engineer digital design | U28: 46194 | V28: v2-cv-accuracy-13b988b18da8ea7d
A29: =IF($L29="applied","Applied",IF($L29="interview","Interview",IF($L29="offer","Offer",IF($L29="rejected","Rejected",IF($L29="ignore","Ignore",IF($L29="archive","Archive",IF($L29="closed","Closed",IF($B29="","Unscored",IF(AND($B29>=8,OR($H29="",$H29-TODAY()<=14)),"P1 Apply",IF($B29>=7,"P2 Strong",IF($B29>=5,"P3 Maybe","P4 Low"))))))))))) | B29: 6.5 | C29: Unspecified | D29: Computer Engineering Expert - AI Content Specialist | E29: Alignerr | F29: London, England, UK | I29: =IF($H29="","",$H29-TODAY()) | J29: Open posting | K29: Same role as above; FPGA, Verilog, embedded systems, and digital logic design strongly align with content specialist requirements. | L29: new | N29: 5ca07c5cf62fb84fc42f4f548049e21619607a4f | O29: 46191 | P29: jobspy | Q29: FPGA, Verilog, embedded systems, digital design, SolidWorks | R29: Graduate Computer Engineer digital design | U29: 46194 | V29: v2-cv-accuracy-13b988b18da8ea7d
A30: =IF($L30="applied","Applied",IF($L30="interview","Interview",IF($L30="offer","Offer",IF($L30="rejected","Rejected",IF($L30="ignore","Ignore",IF($L30="archive","Archive",IF($L30="closed","Closed",IF($B30="","Unscored",IF(AND($B30>=8,OR($H30="",$H30-TODAY()<=14)),"P1 Apply",IF($B30>=7,"P2 Strong",IF($B30>=5,"P3 Maybe","P4 Low"))))))))))) | B30: 6.5 | C30: Unspecified | D30: Computer Engineering | E30: Alignerr | F30: Oxford, England, UK | I30: =IF($H30="","",$H30-TODAY()) | J30: Open posting | K30: FPGA, Verilog, embedded systems, and MEng (pursuing) match well; contract/hourly pay and non-UK currency are minor concerns. | L30: new | N30: 60dec6dfcbf74ff2e76b42a15d50a130e991e554 | O30: 46188 | P30: jobspy | Q30: FPGA, Verilog, embedded systems, digital design, SolidWorks | R30: Graduate Computer Engineer digital design | U30: 46194 | V30: v2-cv-accuracy-13b988b18da8ea7d
A31: =IF($L31="applied","Applied",IF($L31="interview","Interview",IF($L31="offer","Offer",IF($L31="rejected","Rejected",IF($L31="ignore","Ignore",IF($L31="archive","Archive",IF($L31="closed","Closed",IF($B31="","Unscored",IF(AND($B31>=8,OR($H31="",$H31-TODAY()<=14)),"P1 Apply",IF($B31>=7,"P2 Strong",IF($B31>=5,"P3 Maybe","P4 Low"))))))))))) | B31: 6.5 | C31: Unspecified | D31: Computer Engineering | E31: Alignerr | F31: London, England, UK | I31: =IF($H31="","",$H31-TODAY()) | J31: Open posting | K31: FPGA, Verilog, embedded systems, and MEng (pursuing) match well; contract/hourly pay and non-UK currency are minor concerns. | L31: new | N31: 93cab7b860353c713f6fdb5853b08a434ddc3dfa | O31: 46188 | P31: jobspy | Q31: FPGA, Verilog, embedded systems, digital design, SolidWorks | R31: Graduate Computer Engineer digital design | U31: 46194 | V31: v2-cv-accuracy-13b988b18da8ea7d
A32: =IF($L32="applied","Applied",IF($L32="interview","Interview",IF($L32="offer","Offer",IF($L32="rejected","Rejected",IF($L32="ignore","Ignore",IF($L32="archive","Archive",IF($L32="closed","Closed",IF($B32="","Unscored",IF(AND($B32>=8,OR($H32="",$H32-TODAY()<=14)),"P1 Apply",IF($B32>=7,"P2 Strong",IF($B32>=5,"P3 Maybe","P4 Low"))))))))))) | B32: 6.5 | C32: Unspecified | D32: Computer Engineering | E32: Alignerr | F32: Christchurch, England, UK | I32: =IF($H32="","",$H32-TODAY()) | J32: Open posting | K32: FPGA, Verilog, embedded systems, and MEng (pursuing) match well; contract/hourly pay and non-UK currency are minor concerns. | L32: new | N32: 05930b5225024aa12a5a26f832ac99f535a7bbdb | O32: 46188 | P32: jobspy | Q32: FPGA, Verilog, embedded systems, digital design, SolidWorks | R32: Graduate Computer Engineer digital design | U32: 46194 | V32: v2-cv-accuracy-13b988b18da8ea7d
A33: =IF($L33="applied","Applied",IF($L33="interview","Interview",IF($L33="offer","Offer",IF($L33="rejected","Rejected",IF($L33="ignore","Ignore",IF($L33="archive","Archive",IF($L33="closed","Closed",IF($B33="","Unscored",IF(AND($B33>=8,OR($H33="",$H33-TODAY()<=14)),"P1 Apply",IF($B33>=7,"P2 Strong",IF($B33>=5,"P3 Maybe","P4 Low"))))))))))) | B33: 6.5 | C33: Unspecified | D33: Computer Engineering | E33: Alignerr | F33: Glasgow, Scotland, UK | I33: =IF($H33="","",$H33-TODAY()) | J33: Open posting | K33: FPGA, Verilog, embedded systems, and MEng (pursuing) match well; contract/hourly pay and non-UK currency are minor concerns. | L33: new | N33: 4eb8339c75fe77592d166b21e5510f46cc972a06 | O33: 46188 | P33: jobspy | Q33: FPGA, Verilog, embedded systems, digital design, SolidWorks | R33: Graduate Computer Engineer digital design | U33: 46194 | V33: v2-cv-accuracy-13b988b18da8ea7d
A34: =IF($L34="applied","Applied",IF($L34="interview","Interview",IF($L34="offer","Offer",IF($L34="rejected","Rejected",IF($L34="ignore","Ignore",IF($L34="archive","Archive",IF($L34="closed","Closed",IF($B34="","Unscored",IF(AND($B34>=8,OR($H34="",$H34-TODAY()<=14)),"P1 Apply",IF($B34>=7,"P2 Strong",IF($B34>=5,"P3 Maybe","P4 Low"))))))))))) | B34: 6.5 | C34: Unspecified | D34: Computer Engineering | E34: Alignerr | I34: =IF($H34="","",$H34-TODAY()) | J34: Open posting | K34: FPGA, Verilog, embedded systems, and MEng (pursuing) match well; contract/hourly pay and non-UK currency are minor concerns. | L34: new | N34: 8163300ff098715cd31228ae69ab909e61757e1e | O34: 46188 | P34: jobspy | Q34: FPGA, Verilog, embedded systems, digital design, SolidWorks | R34: Graduate Computer Engineer digital design | U34: 46194 | V34: v2-cv-accuracy-13b988b18da8ea7d
A35: =IF($L35="applied","Applied",IF($L35="interview","Interview",IF($L35="offer","Offer",IF($L35="rejected","Rejected",IF($L35="ignore","Ignore",IF($L35="archive","Archive",IF($L35="closed","Closed",IF($B35="","Unscored",IF(AND($B35>=8,OR($H35="",$H35-TODAY()<=14)),"P1 Apply",IF($B35>=7,"P2 Strong",IF($B35>=5,"P3 Maybe","P4 Low"))))))))))) | B35: 6.5 | C35: Senior/Lead | D35: Software Engineer | E35: Metric | F35: London Area, United Kingdom | I35: =IF($H35="","",$H35-TODAY()) | J35: Open posting | K35: Python, Linux, FPGA, embedded systems, and CI/CD match well; lacks production systems experience and C++/Rust, seniority framing slightly above graduate level. | L35: new | N35: 356bcab80ecc693618cdb8180e9db31fdb9f92f8 | O35: 46174 | P35: jobspy | Q35: Python, FPGA, embedded systems, Git, CI/CD | R35: Embedded Software Engineer graduate C Python | U35: 46194 | V35: v2-cv-accuracy-13b988b18da8ea7d
A36: =IF($L36="applied","Applied",IF($L36="interview","Interview",IF($L36="offer","Offer",IF($L36="rejected","Rejected",IF($L36="ignore","Ignore",IF($L36="archive","Archive",IF($L36="closed","Closed",IF($B36="","Unscored",IF(AND($B36>=8,OR($H36="",$H36-TODAY()<=14)),"P1 Apply",IF($B36>=7,"P2 Strong",IF($B36>=5,"P3 Maybe","P4 Low"))))))))))) | B36: 6.5 | C36: Unspecified | D36: Embedded System Engineer | E36: Open Cosmos | F36: Harwell, England, UK | I36: =IF($H36="","",$H36-TODAY()) | J36: Open posting | K36: Verilog, FPGA, and embedded systems match well but C/C++ RTOS proficiency and fault-tolerant space-grade design are gaps. | L36: new | N36: f799d76cb9290d22f3ddec958fb63c3911d1857e | O36: 46181 | P36: jobspy | Q36: Verilog, FPGA, embedded systems, Vivado, sensor integration | R36: Graduate Signal Processing Engineer DSP | U36: 46193 | V36: v2-cv-accuracy-13b988b18da8ea7d
A37: =IF($L37="applied","Applied",IF($L37="interview","Interview",IF($L37="offer","Offer",IF($L37="rejected","Rejected",IF($L37="ignore","Ignore",IF($L37="archive","Archive",IF($L37="closed","Closed",IF($B37="","Unscored",IF(AND($B37>=8,OR($H37="",$H37-TODAY()<=14)),"P1 Apply",IF($B37>=7,"P2 Strong",IF($B37>=5,"P3 Maybe","P4 Low"))))))))))) | B37: 6.5 | C37: Junior | D37: Junior Platform Engineer | E37: Bud Systems | F37: Bristol, ENG, GB | I37: =IF($H37="","",$H37-TODAY()) | J37: Open posting | K37: Good match on Python, SQL, Docker, Kubernetes, Git and CI/CD; SC Clearance eligibility requirement is a potential flag not confirmed in profile. | L37: new | N37: 5b010348e00166189f6e1862022ed946d204e1bf | O37: 46181 | P37: jobspy | Q37: Python, SQL, Docker, Kubernetes, Git | R37: Junior Python Developer SQL Docker | U37: 46193 | V37: v2-cv-accuracy-13b988b18da8ea7d
A38: =IF($L38="applied","Applied",IF($L38="interview","Interview",IF($L38="offer","Offer",IF($L38="rejected","Rejected",IF($L38="ignore","Ignore",IF($L38="archive","Archive",IF($L38="closed","Closed",IF($B38="","Unscored",IF(AND($B38>=8,OR($H38="",$H38-TODAY()<=14)),"P1 Apply",IF($B38>=7,"P2 Strong",IF($B38>=5,"P3 Maybe","P4 Low"))))))))))) | B38: 6.5 | C38: Unspecified | D38: Software Developer | E38: nan | F38: Harrow, ENG, GB | I38: =IF($H38="","",$H38-TODAY()) | J38: Open posting | K38: Python, SQL, Docker, Kubernetes, REST APIs, and JavaScript match well; fintech/banking domain and OAuth2/compliance experience are gaps. | L38: new | N38: e0a174ff327047b93e55ad030810b3af8a33f165 | O38: 46191 | P38: jobspy | Q38: Python, SQL, Docker, Kubernetes, JavaScript | R38: Platform Engineer Docker Kubernetes Python | U38: 46193 | V38: v2-cv-accuracy-13b988b18da8ea7d
A39: =IF($L39="applied","Applied",IF($L39="interview","Interview",IF($L39="offer","Offer",IF($L39="rejected","Rejected",IF($L39="ignore","Ignore",IF($L39="archive","Archive",IF($L39="closed","Closed",IF($B39="","Unscored",IF(AND($B39>=8,OR($H39="",$H39-TODAY()<=14)),"P1 Apply",IF($B39>=7,"P2 Strong",IF($B39>=5,"P3 Maybe","P4 Low"))))))))))) | B39: 6.5 | C39: Mid-level | D39: Verification Engineer (f/m/d) | E39: Renesas Electronics | F39: Edinburgh, Scotland, UK | I39: =IF($H39="","",$H39-TODAY()) | J39: Open posting | K39: Verilog/FPGA ASIC verification role suits profile well; SystemVerilog/UVM gap exists but 2-5 years experience and graduate-level entry align well. | L39: new | N39: 5787a86335d01a78a4ce39707259868b05fb9d30 | O39: 46185 | P39: jobspy | Q39: Verilog, FPGA, Python, Git, digital design | R39: Verification Engineer FPGA Verilog digital | U39: 46193 | V39: v2-cv-accuracy-13b988b18da8ea7d
A40: =IF($L40="applied","Applied",IF($L40="interview","Interview",IF($L40="offer","Offer",IF($L40="rejected","Rejected",IF($L40="ignore","Ignore",IF($L40="archive","Archive",IF($L40="closed","Closed",IF($B40="","Unscored",IF(AND($B40>=8,OR($H40="",$H40-TODAY()<=14)),"P1 Apply",IF($B40>=7,"P2 Strong",IF($B40>=5,"P3 Maybe","P4 Low"))))))))))) | B40: 6.5 | C40: Unspecified | D40: Software Engineer | E40: GlobalLogic | F40: London Area, United Kingdom | I40: =IF($H40="","",$H40-TODAY()) | J40: Open posting | K40: Python, JavaScript, and REST APIs match core skills; role leans toward workflow automation and operations engineering, slightly off target but technically relevant. | L40: new | N40: 22cf1dd318a8ee52173e705cd10025b10315ad6c | O40: 46174 | P40: jobspy | Q40: Python, JavaScript, REST APIs, Git | R40: Junior Python Developer | U40: 46192 | V40: v2-cv-accuracy-13b988b18da8ea7d
...

Sheet runs
A1: ID | B1: Started | C1: Finished | D1: Duration (s) | E1: Sources OK | F1: Sources Failed | G1: Jobs Scraped | H1: Jobs New | I1: Jobs Closed | J1: Errors
A2: 46 | B2: 2026-06-29T16:57:36.969985 | D2: 0 | E2: 5 | F2: 0 | G2: 3833 | H2: 152 | I2: 0 | J2: []
A3: 45 | B3: 2026-06-29T12:19:08.582039 | D3: 0 | E3: 5 | F3: 0 | G3: 4029 | H3: 308 | I3: 0 | J3: []
A4: 44 | B4: 2026-06-28T20:22:27.934906 | D4: 0 | E4: 5 | F4: 0 | G4: 3844 | H4: 168 | I4: 0 | J4: []
A5: 43 | B5: 2026-06-28T15:04:19.953690 | D5: 0 | E5: 5 | F5: 0 | G5: 3735 | H5: 104 | I5: 0 | J5: []
A6: 42 | B6: 2026-06-28T10:17:59.891534 | D6: 0 | E6: 5 | F6: 0 | G6: 3248 | H6: 0 | I6: 0 | J6: []
A7: 41 | B7: 2026-06-27T20:27:13.121548 | D7: 0 | E7: 5 | F7: 0 | G7: 4106 | H7: 320 | I7: 0 | J7: []
A8: 40 | B8: 2026-06-27T14:45:35.702722 | D8: 0 | E8: 5 | F8: 0 | G8: 3837 | H8: 189 | I8: 0 | J8: []
A9: 39 | B9: 2026-06-27T09:41:27.016531 | D9: 0 | E9: 5 | F9: 0 | G9: 3648 | H9: 185 | I9: 0 | J9: []
A10: 38 | B10: 2026-06-26T20:49:37.549966 | D10: 0 | E10: 5 | F10: 0 | G10: 3866 | H10: 212 | I10: 0 | J10: []
A11: 37 | B11: 2026-06-26T20:08:19.603896 | D11: 0 | E11: 5 | F11: 0 | G11: 3763 | H11: 2161 | I11: 0 | J11: []
A12: 36 | B12: 2026-06-26T15:29:12.111224 | D12: 0 | E12: 5 | F12: 0 | G12: 823 | H12: 37 | I12: 0 | J12: []
A13: 35 | B13: 2026-06-26T10:22:20.681134 | D13: 0 | E13: 5 | F13: 0 | G13: 854 | H13: 13 | I13: 0 | J13: []
... A31: 17 | B31: 2026-06-20T15:15:13.727639 | D31: 0 | E31: 5 | F31: 0 | G31: 950 | H31: 60 | I31: 0 | J31: []

Sheet profile
A1: Key | B1: Value
A2: name | B2: David Cracknell
A3: domain | B3: engineering
A4: secondary_domains | B4: ["finance", "science"]
A5: location.city | B5: Sheffield
A6: location.lat | B6: 53.38
A7: location.lon | B7: -1.47
A8: search_radius_miles | B8: 60
A9: remote_ok | B9: true
A10: education.highest_qualification | B10: MEng Electronic and Computer Engineering
A11: education.institution | B11: University of Sheffield
A12: education.completion_year | B12: 2026
... A30: filters.rejected_company_cooldown_days | B30: 90

Sheet quota
A1: Date | B1: Operation | C1: Model | D1: Calls | E1: Input Tokens | F1: Cached Tokens | G1: Output Tokens | H1: Est. Cost (GBP)
A2: 2026-06-29 | B2: queries | C2: claude-sonnet-4-6 | D2: 2 | E2: 4188 | F2: 0 | G2: 1203 | H2: 0.0245
A3: 2026-06-29 | B3: rank | D3: 1177 | E3: 0 | F3: 0 | G3: 0 | H3: 0
A4: 2026-06-28 | B4: queries | C4: claude-sonnet-4-6 | D4: 3 | E4: 6282 | F4: 0 | G4: 1818 | H4: 0.0369
A5: 2026-06-28 | B5: rank | D5: 1609 | E5: 0 | F5: 0 | G5: 0 | H5: 0
A6: 2026-06-27 | B6: queries | C6: claude-sonnet-4-6 | D6: 3 | E6: 6282 | F6: 0 | G6: 1778 | H6: 0.0364
A7: 2026-06-27 | B7: rank | D7: 1724 | E7: 0 | F7: 0 | G7: 0 | H7: 0
A8: 2026-06-26 | B8: rank | C8: claude-sonnet-4-6 | D8: 9 | E8: 31423 | F8: 12775 | G8: 3103 | H8: 0.0851
A9: 2026-06-26 | B9: queries | C9: claude-sonnet-4-6 | D9: 4 | E9: 6642 | F9: 0 | G9: 1705 | H9: 0.0364
A10: 2026-06-26 | B10: rank | D10: 1132 | E10: 0 | F10: 0 | G10: 0 | H10: 0
A11: 2026-06-25 | B11: rank | C11: claude-sonnet-4-6 | D11: 9 | E11: 31761 | F11: 10950 | G11: 3043 | H11: 0.0891
A12: 2026-06-25 | B12: queries | C12: claude-sonnet-4-6 | D12: 3 | E12: 3681 | F12: 0 | G12: 794 | H12: 0.0184
A13: 2026-06-24 | B13: rank | C13: claude-sonnet-4-6 | D13: 10 | E13: 34789 | F13: 12775 | G13: 3302 | H13: 0.0965
A14: 2026-06-24 | B14: queries | C14: claude-sonnet-4-6 | D14: 3 | E14: 3681 | F14: 0 | G14: 794 | H14: 0.0184
A15: 2026-06-23 | B15: rank | C15: claude-sonnet-4-6 | D15: 10 | E15: 29842 | F15: 12775 | G15: 2984 | H15: 0.0823
A16: 2026-06-23 | B16: queries | C16: claude-sonnet-4-6 | D16: 3 | E16: 3681 | F16: 0 | G16: 797 | H16: 0.0184
A17: 2026-06-22 | B17: rank | C17: claude-sonnet-4-6 | D17: 15 | E17: 51247 | F17: 18255 | G17: 4967 | H17: 0.1452
A18: 2026-06-22 | B18: queries | C18: claude-sonnet-4-6 | D18: 4 | E18: 4362 | F18: 0 | G18: 991 | H18: 0.0224
A19: 2026-06-21 | B19: rank | C19: claude-sonnet-4-6 | D19: 11 | E19: 35469 | F19: 13144 | G19: 3662 | H19: 0.1027
A20: 2026-06-21 | B20: queries | C20: claude-sonnet-4-6 | D20: 3 | E20: 3135 | F20: 0 | G20: 710 | H20: 0.016
A21: 2026-06-20 | B21: rank | C21: claude-sonnet-4-6 | D21: 17 | E21: 58173 | F21: 23002 | G21: 5580 | H21: 0.1598
A22: 2026-06-20 | B22: queries | C22: claude-sonnet-4-6 | D22: 3 | E22: 3135 | F22: 0 | G22: 730 | H22: 0.0163
... A24: 2026-06-19 | B24: queries | C24: claude-sonnet-4-6 | D24: 3 | E24: 3135 | F24: 0 | G24: 730 | H24: 0.0163
A25: 2026-06-19 | B25: queries | D25: 1 | E25: 0 | F25: 0 | G25: 0 | H25: 0
A26: 2026-06-18 | B26: queries | D26: 8 | E26: 0 | F26: 0 | G26: 0 | H26: 0
A27: 2026-06-18 | B27: rank | D27: 129 | E27: 0 | F27: 0 | G27: 0 | H27: 0
A28: 2026-06-17 | B28: rank | D28: 35 | E28: 0 | F28: 0 | G28: 0 | H28: 0
A29: 2026-06-16 | B29: rank | D29: 70 | E29: 0 | F29: 0 | G29: 0 | H29: 0
